FAISS vector store created with 6441 documents.
Traceback (most recent call last):
  File "/home/halil/.pyenv/versions/DI502/lib/python3.10/site-packages/urllib3/connectionpool.py", line 789, in urlopen
    response = self._make_request(
  File "/home/halil/.pyenv/versions/DI502/lib/python3.10/site-packages/urllib3/connectionpool.py", line 536, in _make_request
    response = conn.getresponse()
  File "/home/halil/.pyenv/versions/DI502/lib/python3.10/site-packages/urllib3/connection.py", line 507, in getresponse
    httplib_response = super().getresponse()
  File "/home/halil/.pyenv/versions/3.10.4/lib/python3.10/http/client.py", line 1374, in getresponse
    response.begin()
  File "/home/halil/.pyenv/versions/3.10.4/lib/python3.10/http/client.py", line 318, in begin
    version, status, reason = self._read_status()
  File "/home/halil/.pyenv/versions/3.10.4/lib/python3.10/http/client.py", line 287, in _read_status
    raise RemoteDisconnected("Remote end closed connection without"
http.client.RemoteDisconnected: Remote end closed connection without response

During handling of the above exception, another exception occurred:

Traceback (most recent call last):
  File "/home/halil/.pyenv/versions/DI502/lib/python3.10/site-packages/requests/adapters.py", line 667, in send
    resp = conn.urlopen(
  File "/home/halil/.pyenv/versions/DI502/lib/python3.10/site-packages/urllib3/connectionpool.py", line 843, in urlopen
    retries = retries.increment(
  File "/home/halil/.pyenv/versions/DI502/lib/python3.10/site-packages/urllib3/util/retry.py", line 474, in increment
    raise reraise(type(error), error, _stacktrace)
  File "/home/halil/.pyenv/versions/DI502/lib/python3.10/site-packages/urllib3/util/util.py", line 38, in reraise
    raise value.with_traceback(tb)
  File "/home/halil/.pyenv/versions/DI502/lib/python3.10/site-packages/urllib3/connectionpool.py", line 789, in urlopen
    response = self._make_request(
  File "/home/halil/.pyenv/versions/DI502/lib/python3.10/site-packages/urllib3/connectionpool.py", line 536, in _make_request
    response = conn.getresponse()
  File "/home/halil/.pyenv/versions/DI502/lib/python3.10/site-packages/urllib3/connection.py", line 507, in getresponse
    httplib_response = super().getresponse()
  File "/home/halil/.pyenv/versions/3.10.4/lib/python3.10/http/client.py", line 1374, in getresponse
    response.begin()
  File "/home/halil/.pyenv/versions/3.10.4/lib/python3.10/http/client.py", line 318, in begin
    version, status, reason = self._read_status()
  File "/home/halil/.pyenv/versions/3.10.4/lib/python3.10/http/client.py", line 287, in _read_status
    raise RemoteDisconnected("Remote end closed connection without"
urllib3.exceptions.ProtocolError: ('Connection aborted.', RemoteDisconnected('Remote end closed connection without response'))

During handling of the above exception, another exception occurred:

Traceback (most recent call last):
  File "/home/halil/Desktop/MeETU/RAG_Model/meetu_wandb/meetu_wandb_main.py", line 164, in sweep_fn
    results, results_df, results_df_metrics_stats, average_latency = meetu_evaluate_metrics(
  File "/home/halil/Desktop/MeETU/RAG_Model/meetu_wandb/meetu_test_eval.py", line 110, in meetu_evaluate_metrics
    test_data["response"], test_data["retrieved_contexts"], test_data["latency"] = zip(*test_data["user_input"].apply(meetu_generate_response))
  File "/home/halil/.pyenv/versions/DI502/lib/python3.10/site-packages/pandas/core/series.py", line 4924, in apply
    ).apply()
  File "/home/halil/.pyenv/versions/DI502/lib/python3.10/site-packages/pandas/core/apply.py", line 1427, in apply
    return self.apply_standard()
  File "/home/halil/.pyenv/versions/DI502/lib/python3.10/site-packages/pandas/core/apply.py", line 1507, in apply_standard
    mapped = obj._map_values(
  File "/home/halil/.pyenv/versions/DI502/lib/python3.10/site-packages/pandas/core/base.py", line 921, in _map_values
    return algorithms.map_array(arr, mapper, na_action=na_action, convert=convert)
  File "/home/halil/.pyenv/versions/DI502/lib/python3.10/site-packages/pandas/core/algorithms.py", line 1743, in map_array
    return lib.map_infer(values, mapper, convert=convert)
  File "lib.pyx", line 2972, in pandas._libs.lib.map_infer
  File "/home/halil/Desktop/MeETU/RAG_Model/meetu_wandb/meetu_test_eval.py", line 98, in meetu_generate_response
    response, context = generate_chain_output(row)
  File "/home/halil/Desktop/MeETU/RAG_Model/meetu_wandb/meetu_test_eval.py", line 49, in generate_chain_output
    chain_output = rag_chain.invoke(question)
  File "/home/halil/.pyenv/versions/DI502/lib/python3.10/site-packages/langchain_core/runnables/base.py", line 3024, in invoke
    input = context.run(step.invoke, input, config)
  File "/home/halil/.pyenv/versions/DI502/lib/python3.10/site-packages/langchain_core/language_models/llms.py", line 390, in invoke
    self.generate_prompt(
  File "/home/halil/.pyenv/versions/DI502/lib/python3.10/site-packages/langchain_core/language_models/llms.py", line 755, in generate_prompt
    return self.generate(prompt_strings, stop=stop, callbacks=callbacks, **kwargs)
  File "/home/halil/.pyenv/versions/DI502/lib/python3.10/site-packages/langchain_core/language_models/llms.py", line 950, in generate
    output = self._generate_helper(
  File "/home/halil/.pyenv/versions/DI502/lib/python3.10/site-packages/langchain_core/language_models/llms.py", line 792, in _generate_helper
    raise e
  File "/home/halil/.pyenv/versions/DI502/lib/python3.10/site-packages/langchain_core/language_models/llms.py", line 779, in _generate_helper
    self._generate(
  File "/home/halil/.pyenv/versions/DI502/lib/python3.10/site-packages/langchain_core/language_models/llms.py", line 1502, in _generate
    self._call(prompt, stop=stop, run_manager=run_manager, **kwargs)
  File "/home/halil/.pyenv/versions/DI502/lib/python3.10/site-packages/langchain_huggingface/llms/huggingface_endpoint.py", line 312, in _call
    response = self.client.post(
  File "/home/halil/.pyenv/versions/DI502/lib/python3.10/site-packages/huggingface_hub/inference/_client.py", line 259, in post
    response = get_session().post(
  File "/home/halil/.pyenv/versions/DI502/lib/python3.10/site-packages/requests/sessions.py", line 637, in post
    return self.request("POST", url, data=data, json=json, **kwargs)
  File "/home/halil/.pyenv/versions/DI502/lib/python3.10/site-packages/requests/sessions.py", line 589, in request
    resp = self.send(prep, **send_kwargs)
  File "/home/halil/.pyenv/versions/DI502/lib/python3.10/site-packages/requests/sessions.py", line 703, in send
    r = adapter.send(request, **kwargs)
  File "/home/halil/.pyenv/versions/DI502/lib/python3.10/site-packages/huggingface_hub/utils/_http.py", line 66, in send
    return super().send(request, *args, **kwargs)
  File "/home/halil/.pyenv/versions/DI502/lib/python3.10/site-packages/requests/adapters.py", line 682, in send
    raise ConnectionError(err, request=request)
requests.exceptions.ConnectionError: (ProtocolError('Connection aborted.', RemoteDisconnected('Remote end closed connection without response')), '(Request ID: 8e491816-9b50-48e3-9c24-280ddf7ad96a)')
