FAISS vector store created with 6441 documents.
Evaluating:  29%|████████████████████████████████████████████████████████▍                                                                                                                                             | 191/670 [02:39<10:26,  1.31s/it]Task exception was never retrieved
future: <Task finished name='Task-23614' coro=<AsyncClient.aclose() done, defined at /home/halil/.pyenv/versions/DI502/lib/python3.10/site-packages/httpx/_client.py:2024> exception=RuntimeError('Event loop is closed')>
Traceback (most recent call last):
  File "/home/halil/.pyenv/versions/DI502/lib/python3.10/site-packages/httpx/_client.py", line 2031, in aclose
    await self._transport.aclose()
  File "/home/halil/.pyenv/versions/DI502/lib/python3.10/site-packages/httpx/_transports/default.py", line 389, in aclose
    await self._pool.aclose()
  File "/home/halil/.pyenv/versions/DI502/lib/python3.10/site-packages/httpcore/_async/connection_pool.py", line 313, in aclose
    await self._close_connections(closing_connections)
  File "/home/halil/.pyenv/versions/DI502/lib/python3.10/site-packages/httpcore/_async/connection_pool.py", line 305, in _close_connections
    await connection.aclose()
  File "/home/halil/.pyenv/versions/DI502/lib/python3.10/site-packages/httpcore/_async/connection.py", line 171, in aclose
    await self._connection.aclose()
  File "/home/halil/.pyenv/versions/DI502/lib/python3.10/site-packages/httpcore/_async/http11.py", line 265, in aclose
    await self._network_stream.aclose()
  File "/home/halil/.pyenv/versions/DI502/lib/python3.10/site-packages/httpcore/_backends/anyio.py", line 55, in aclose
    await self._stream.aclose()
  File "/home/halil/.pyenv/versions/DI502/lib/python3.10/site-packages/anyio/streams/tls.py", line 201, in aclose
    await self.transport_stream.aclose()
  File "/home/halil/.pyenv/versions/DI502/lib/python3.10/site-packages/anyio/_backends/_asyncio.py", line 1287, in aclose
    self._transport.close()
  File "/home/halil/.pyenv/versions/3.10.4/lib/python3.10/asyncio/selector_events.py", line 697, in close
    self._loop.call_soon(self._call_connection_lost, None)
  File "/home/halil/.pyenv/versions/3.10.4/lib/python3.10/asyncio/base_events.py", line 750, in call_soon
    self._check_closed()
  File "/home/halil/.pyenv/versions/3.10.4/lib/python3.10/asyncio/base_events.py", line 515, in _check_closed
    raise RuntimeError('Event loop is closed')
RuntimeError: Event loop is closed
Task exception was never retrieved
future: <Task finished name='Task-23615' coro=<AsyncClient.aclose() done, defined at /home/halil/.pyenv/versions/DI502/lib/python3.10/site-packages/httpx/_client.py:2024> exception=RuntimeError('Event loop is closed')>
Traceback (most recent call last):
  File "/home/halil/.pyenv/versions/DI502/lib/python3.10/site-packages/httpx/_client.py", line 2031, in aclose
    await self._transport.aclose()
  File "/home/halil/.pyenv/versions/DI502/lib/python3.10/site-packages/httpx/_transports/default.py", line 389, in aclose
    await self._pool.aclose()
  File "/home/halil/.pyenv/versions/DI502/lib/python3.10/site-packages/httpcore/_async/connection_pool.py", line 313, in aclose
    await self._close_connections(closing_connections)
  File "/home/halil/.pyenv/versions/DI502/lib/python3.10/site-packages/httpcore/_async/connection_pool.py", line 305, in _close_connections
    await connection.aclose()
  File "/home/halil/.pyenv/versions/DI502/lib/python3.10/site-packages/httpcore/_async/connection.py", line 171, in aclose
    await self._connection.aclose()
  File "/home/halil/.pyenv/versions/DI502/lib/python3.10/site-packages/httpcore/_async/http11.py", line 265, in aclose
    await self._network_stream.aclose()
  File "/home/halil/.pyenv/versions/DI502/lib/python3.10/site-packages/httpcore/_backends/anyio.py", line 55, in aclose
    await self._stream.aclose()
  File "/home/halil/.pyenv/versions/DI502/lib/python3.10/site-packages/anyio/streams/tls.py", line 201, in aclose
    await self.transport_stream.aclose()
  File "/home/halil/.pyenv/versions/DI502/lib/python3.10/site-packages/anyio/_backends/_asyncio.py", line 1287, in aclose
    self._transport.close()
  File "/home/halil/.pyenv/versions/3.10.4/lib/python3.10/asyncio/selector_events.py", line 697, in close
    self._loop.call_soon(self._call_connection_lost, None)
  File "/home/halil/.pyenv/versions/3.10.4/lib/python3.10/asyncio/base_events.py", line 750, in call_soon
    self._check_closed()
  File "/home/halil/.pyenv/versions/3.10.4/lib/python3.10/asyncio/base_events.py", line 515, in _check_closed
    raise RuntimeError('Event loop is closed')
RuntimeError: Event loop is closed
Evaluating:  56%|██████████████████████████████████████████████████████████████████████████████████████████████████████████████▏                                                                                       | 373/670 [05:31<03:00,  1.65it/s]Exception raised in Job[199]: TimeoutError()
Evaluating: 100%|██████████████████████████████████████████████████████████████████████████████████████████████████████████████████████████████████████████████████████████████████████████████████████████████████████| 670/670 [11:52<00:00,  1.06s/it]
